2018-03-04 16:59:46,397 ERROR: Exception on /user/newuser [GET] [in /home/mark/anaconda3/envs/flask/lib/python3.6/site-packages/flask/app.py:1560]
Traceback (most recent call last):
  File "/home/mark/anaconda3/envs/flask/lib/python3.6/site-packages/flask/app.py", line 1982, in wsgi_app
    response = self.full_dispatch_request()
  File "/home/mark/anaconda3/envs/flask/lib/python3.6/site-packages/flask/app.py", line 1614, in full_dispatch_request
    rv = self.handle_user_exception(e)
  File "/home/mark/anaconda3/envs/flask/lib/python3.6/site-packages/flask/app.py", line 1517, in handle_user_exception
    reraise(exc_type, exc_value, tb)
  File "/home/mark/anaconda3/envs/flask/lib/python3.6/site-packages/flask/_compat.py", line 33, in reraise
    raise value
  File "/home/mark/anaconda3/envs/flask/lib/python3.6/site-packages/flask/app.py", line 1612, in full_dispatch_request
    rv = self.dispatch_request()
  File "/home/mark/anaconda3/envs/flask/lib/python3.6/site-packages/flask/app.py", line 1598, in dispatch_request
    return self.view_functions[rule.endpoint](**req.view_args)
  File "/home/mark/anaconda3/envs/flask/lib/python3.6/site-packages/flask_login/utils.py", line 261, in decorated_view
    return func(*args, **kwargs)
  File "/home/mark/PythonFlaskBlog/app/routes.py", line 25, in user
    return render_template('user.html', user=user, posts=posts)
  File "/home/mark/anaconda3/envs/flask/lib/python3.6/site-packages/flask/templating.py", line 134, in render_template
    context, ctx.app)
  File "/home/mark/anaconda3/envs/flask/lib/python3.6/site-packages/flask/templating.py", line 116, in _render
    rv = template.render(context)
  File "/home/mark/anaconda3/envs/flask/lib/python3.6/site-packages/jinja2/asyncsupport.py", line 76, in render
    return original_render(self, *args, **kwargs)
  File "/home/mark/anaconda3/envs/flask/lib/python3.6/site-packages/jinja2/environment.py", line 1008, in render
    return self.environment.handle_exception(exc_info, True)
  File "/home/mark/anaconda3/envs/flask/lib/python3.6/site-packages/jinja2/environment.py", line 780, in handle_exception
    reraise(exc_type, exc_value, tb)
  File "/home/mark/anaconda3/envs/flask/lib/python3.6/site-packages/jinja2/_compat.py", line 37, in reraise
    raise value.with_traceback(tb)
  File "/home/mark/PythonFlaskBlog/app/templates/user.html", line 1, in top-level template code
    {% extends "base.html" %}
  File "/home/mark/PythonFlaskBlog/app/templates/base.html", line 29, in top-level template code
    {% block content %}{% endblock %}
  File "/home/mark/PythonFlaskBlog/app/templates/user.html", line 16, in block "content"
    <p><a href="{{ url_for('follow', username=user.username) }}">Follow</a></p>
  File "/home/mark/anaconda3/envs/flask/lib/python3.6/site-packages/flask/helpers.py", line 333, in url_for
    return appctx.app.handle_url_build_error(error, endpoint, values)
  File "/home/mark/anaconda3/envs/flask/lib/python3.6/site-packages/flask/app.py", line 1805, in handle_url_build_error
    reraise(exc_type, exc_value, tb)
  File "/home/mark/anaconda3/envs/flask/lib/python3.6/site-packages/flask/_compat.py", line 33, in reraise
    raise value
  File "/home/mark/anaconda3/envs/flask/lib/python3.6/site-packages/flask/helpers.py", line 323, in url_for
    force_external=external)
  File "/home/mark/anaconda3/envs/flask/lib/python3.6/site-packages/werkzeug/routing.py", line 1776, in build
    raise BuildError(endpoint, values, method, self)
werkzeug.routing.BuildError: Could not build url for endpoint 'follow' with values ['username']. Did you mean 'unfollow' instead?
2018-03-04 17:52:40,559 INFO: Microblog startup [in /home/mark/PythonFlaskBlog/app/__init__.py:44]
2018-03-04 17:55:51,333 INFO: Microblog startup [in /home/mark/PythonFlaskBlog/app/__init__.py:44]
2018-03-04 17:57:12,971 ERROR: Exception on /user/mark [GET] [in /home/mark/anaconda3/envs/flask/lib/python3.6/site-packages/flask/app.py:1560]
Traceback (most recent call last):
  File "/home/mark/anaconda3/envs/flask/lib/python3.6/site-packages/flask/app.py", line 1982, in wsgi_app
    response = self.full_dispatch_request()
  File "/home/mark/anaconda3/envs/flask/lib/python3.6/site-packages/flask/app.py", line 1614, in full_dispatch_request
    rv = self.handle_user_exception(e)
  File "/home/mark/anaconda3/envs/flask/lib/python3.6/site-packages/flask/app.py", line 1517, in handle_user_exception
    reraise(exc_type, exc_value, tb)
  File "/home/mark/anaconda3/envs/flask/lib/python3.6/site-packages/flask/_compat.py", line 33, in reraise
    raise value
  File "/home/mark/anaconda3/envs/flask/lib/python3.6/site-packages/flask/app.py", line 1612, in full_dispatch_request
    rv = self.dispatch_request()
  File "/home/mark/anaconda3/envs/flask/lib/python3.6/site-packages/flask/app.py", line 1598, in dispatch_request
    return self.view_functions[rule.endpoint](**req.view_args)
  File "/home/mark/anaconda3/envs/flask/lib/python3.6/site-packages/flask_login/utils.py", line 261, in decorated_view
    return func(*args, **kwargs)
  File "/home/mark/PythonFlaskBlog/app/routes.py", line 25, in user
    return render_template('user.html', user=user, posts=posts)
  File "/home/mark/anaconda3/envs/flask/lib/python3.6/site-packages/flask/templating.py", line 134, in render_template
    context, ctx.app)
  File "/home/mark/anaconda3/envs/flask/lib/python3.6/site-packages/flask/templating.py", line 116, in _render
    rv = template.render(context)
  File "/home/mark/anaconda3/envs/flask/lib/python3.6/site-packages/jinja2/asyncsupport.py", line 76, in render
    return original_render(self, *args, **kwargs)
  File "/home/mark/anaconda3/envs/flask/lib/python3.6/site-packages/jinja2/environment.py", line 1008, in render
    return self.environment.handle_exception(exc_info, True)
  File "/home/mark/anaconda3/envs/flask/lib/python3.6/site-packages/jinja2/environment.py", line 780, in handle_exception
    reraise(exc_type, exc_value, tb)
  File "/home/mark/anaconda3/envs/flask/lib/python3.6/site-packages/jinja2/_compat.py", line 37, in reraise
    raise value.with_traceback(tb)
  File "/home/mark/PythonFlaskBlog/app/templates/user.html", line 1, in top-level template code
    {% extends "base.html" %}
  File "/home/mark/PythonFlaskBlog/app/templates/base.html", line 29, in top-level template code
    {% block content %}{% endblock %}
  File "/home/mark/PythonFlaskBlog/app/templates/user.html", line 16, in block "content"
    <p><a href="{{ url_for('follow', username=user.username) }}">Follow</a></p>
  File "/home/mark/anaconda3/envs/flask/lib/python3.6/site-packages/flask/helpers.py", line 333, in url_for
    return appctx.app.handle_url_build_error(error, endpoint, values)
  File "/home/mark/anaconda3/envs/flask/lib/python3.6/site-packages/flask/app.py", line 1805, in handle_url_build_error
    reraise(exc_type, exc_value, tb)
  File "/home/mark/anaconda3/envs/flask/lib/python3.6/site-packages/flask/_compat.py", line 33, in reraise
    raise value
  File "/home/mark/anaconda3/envs/flask/lib/python3.6/site-packages/flask/helpers.py", line 323, in url_for
    force_external=external)
  File "/home/mark/anaconda3/envs/flask/lib/python3.6/site-packages/werkzeug/routing.py", line 1776, in build
    raise BuildError(endpoint, values, method, self)
werkzeug.routing.BuildError: Could not build url for endpoint 'follow' with values ['username']. Did you mean 'unfollow' instead?
