2018-04-02 11:54:17,004 ERROR: Exception on /edit_object/2 [POST] [in /home/mark/anaconda3/envs/flask/lib/python3.6/site-packages/flask/app.py:1560]
Traceback (most recent call last):
  File "/home/mark/anaconda3/envs/flask/lib/python3.6/site-packages/sqlalchemy/engine/base.py", line 1193, in _execute_context
    context)
  File "/home/mark/anaconda3/envs/flask/lib/python3.6/site-packages/sqlalchemy/engine/default.py", line 507, in do_execute
    cursor.execute(statement, parameters)
psycopg2.IntegrityError: insert or update on table "db_object" violates foreign key constraint "db_object_project_id_fkey"
DETAIL:  Key (project_id)=(234567) is not present in table "project".


The above exception was the direct cause of the following exception:

Traceback (most recent call last):
  File "/home/mark/anaconda3/envs/flask/lib/python3.6/site-packages/flask/app.py", line 1982, in wsgi_app
    response = self.full_dispatch_request()
  File "/home/mark/anaconda3/envs/flask/lib/python3.6/site-packages/flask/app.py", line 1614, in full_dispatch_request
    rv = self.handle_user_exception(e)
  File "/home/mark/anaconda3/envs/flask/lib/python3.6/site-packages/flask/app.py", line 1517, in handle_user_exception
    reraise(exc_type, exc_value, tb)
  File "/home/mark/anaconda3/envs/flask/lib/python3.6/site-packages/flask/_compat.py", line 33, in reraise
    raise value
  File "/home/mark/anaconda3/envs/flask/lib/python3.6/site-packages/flask/app.py", line 1612, in full_dispatch_request
    rv = self.dispatch_request()
  File "/home/mark/anaconda3/envs/flask/lib/python3.6/site-packages/flask/app.py", line 1598, in dispatch_request
    return self.view_functions[rule.endpoint](**req.view_args)
  File "/home/mark/PythonFlaskVertica/app/routes.py", line 240, in edit_object
    db.session.commit()
  File "/home/mark/anaconda3/envs/flask/lib/python3.6/site-packages/sqlalchemy/orm/scoping.py", line 153, in do
    return getattr(self.registry(), name)(*args, **kwargs)
  File "/home/mark/anaconda3/envs/flask/lib/python3.6/site-packages/sqlalchemy/orm/session.py", line 943, in commit
    self.transaction.commit()
  File "/home/mark/anaconda3/envs/flask/lib/python3.6/site-packages/sqlalchemy/orm/session.py", line 467, in commit
    self._prepare_impl()
  File "/home/mark/anaconda3/envs/flask/lib/python3.6/site-packages/sqlalchemy/orm/session.py", line 447, in _prepare_impl
    self.session.flush()
  File "/home/mark/anaconda3/envs/flask/lib/python3.6/site-packages/sqlalchemy/orm/session.py", line 2243, in flush
    self._flush(objects)
  File "/home/mark/anaconda3/envs/flask/lib/python3.6/site-packages/sqlalchemy/orm/session.py", line 2369, in _flush
    transaction.rollback(_capture_exception=True)
  File "/home/mark/anaconda3/envs/flask/lib/python3.6/site-packages/sqlalchemy/util/langhelpers.py", line 66, in __exit__
    compat.reraise(exc_type, exc_value, exc_tb)
  File "/home/mark/anaconda3/envs/flask/lib/python3.6/site-packages/sqlalchemy/util/compat.py", line 187, in reraise
    raise value
  File "/home/mark/anaconda3/envs/flask/lib/python3.6/site-packages/sqlalchemy/orm/session.py", line 2333, in _flush
    flush_context.execute()
  File "/home/mark/anaconda3/envs/flask/lib/python3.6/site-packages/sqlalchemy/orm/unitofwork.py", line 391, in execute
    rec.execute(self)
  File "/home/mark/anaconda3/envs/flask/lib/python3.6/site-packages/sqlalchemy/orm/unitofwork.py", line 556, in execute
    uow
  File "/home/mark/anaconda3/envs/flask/lib/python3.6/site-packages/sqlalchemy/orm/persistence.py", line 177, in save_obj
    mapper, table, update)
  File "/home/mark/anaconda3/envs/flask/lib/python3.6/site-packages/sqlalchemy/orm/persistence.py", line 768, in _emit_update_statements
    execute(statement, multiparams)
  File "/home/mark/anaconda3/envs/flask/lib/python3.6/site-packages/sqlalchemy/engine/base.py", line 948, in execute
    return meth(self, multiparams, params)
  File "/home/mark/anaconda3/envs/flask/lib/python3.6/site-packages/sqlalchemy/sql/elements.py", line 269, in _execute_on_connection
    return connection._execute_clauseelement(self, multiparams, params)
  File "/home/mark/anaconda3/envs/flask/lib/python3.6/site-packages/sqlalchemy/engine/base.py", line 1060, in _execute_clauseelement
    compiled_sql, distilled_params
  File "/home/mark/anaconda3/envs/flask/lib/python3.6/site-packages/sqlalchemy/engine/base.py", line 1200, in _execute_context
    context)
  File "/home/mark/anaconda3/envs/flask/lib/python3.6/site-packages/sqlalchemy/engine/base.py", line 1413, in _handle_dbapi_exception
    exc_info
  File "/home/mark/anaconda3/envs/flask/lib/python3.6/site-packages/sqlalchemy/util/compat.py", line 203, in raise_from_cause
    reraise(type(exception), exception, tb=exc_tb, cause=cause)
  File "/home/mark/anaconda3/envs/flask/lib/python3.6/site-packages/sqlalchemy/util/compat.py", line 186, in reraise
    raise value.with_traceback(tb)
  File "/home/mark/anaconda3/envs/flask/lib/python3.6/site-packages/sqlalchemy/engine/base.py", line 1193, in _execute_context
    context)
  File "/home/mark/anaconda3/envs/flask/lib/python3.6/site-packages/sqlalchemy/engine/default.py", line 507, in do_execute
    cursor.execute(statement, parameters)
sqlalchemy.exc.IntegrityError: (psycopg2.IntegrityError) insert or update on table "db_object" violates foreign key constraint "db_object_project_id_fkey"
DETAIL:  Key (project_id)=(234567) is not present in table "project".
 [SQL: 'UPDATE db_object SET project_id=%(project_id)s WHERE db_object.id = %(db_object_id)s'] [parameters: {'project_id': '234567', 'db_object_id': 2}] (Background on this error at: http://sqlalche.me/e/gkpj)
2018-04-02 12:29:05,994 INFO: Microblog startup [in /home/mark/PythonFlaskVertica/app/__init__.py:49]
2018-04-02 12:29:05,996 INFO: Microblog startup [in /home/mark/PythonFlaskVertica/app/__init__.py:67]
2018-04-02 12:29:05,996 INFO: Microblog startup [in /home/mark/PythonFlaskVertica/app/__init__.py:67]
